/net/tscratch/people/plgfilipeckijan/.conda/envs/zzsn_project_env/lib/python3.9/site-packages/transformers/utils/hub.py:124: FutureWarning: Using `TRANSFORMERS_CACHE` is deprecated and will be removed in v5 of Transformers. Use `HF_HOME` instead.
  warnings.warn(
The following values were not passed to `accelerate launch` and had defaults used instead:
	`--num_processes` was set to a value of `1`
	`--num_machines` was set to a value of `1`
	`--mixed_precision` was set to a value of `'no'`
	`--dynamo_backend` was set to a value of `'no'`
To avoid this warning pass in values for each of the problematic parameters or run `accelerate config`.
/net/tscratch/people/plgfilipeckijan/.conda/envs/zzsn_project_env/lib/python3.9/site-packages/transformers/utils/hub.py:124: FutureWarning: Using `TRANSFORMERS_CACHE` is deprecated and will be removed in v5 of Transformers. Use `HF_HOME` instead.
  warnings.warn(
Traceback (most recent call last):
  File "/net/tscratch/people/plgfilipeckijan/zzsn-project/calculate_dino.py", line 8, in <module>
    from transformers import DINOModel, DINOImageProcessor
ImportError: cannot import name 'DINOModel' from 'transformers' (/net/tscratch/people/plgfilipeckijan/.conda/envs/zzsn_project_env/lib/python3.9/site-packages/transformers/__init__.py)
Traceback (most recent call last):
  File "/net/tscratch/people/plgfilipeckijan/.conda/envs/zzsn_project_env/bin/accelerate", line 8, in <module>
    sys.exit(main())
  File "/net/tscratch/people/plgfilipeckijan/.conda/envs/zzsn_project_env/lib/python3.9/site-packages/accelerate/commands/accelerate_cli.py", line 46, in main
    args.func(args)
  File "/net/tscratch/people/plgfilipeckijan/.conda/envs/zzsn_project_env/lib/python3.9/site-packages/accelerate/commands/launch.py", line 1075, in launch_command
    simple_launcher(args)
  File "/net/tscratch/people/plgfilipeckijan/.conda/envs/zzsn_project_env/lib/python3.9/site-packages/accelerate/commands/launch.py", line 681, in simple_launcher
    raise subprocess.CalledProcessError(returncode=process.returncode, cmd=cmd)
subprocess.CalledProcessError: Command '['/net/tscratch/people/plgfilipeckijan/.conda/envs/zzsn_project_env/bin/python', 'calculate_dino.py', '--original_dir=./dataset/dreambooth-main/dataset/dog6', '--generated_dir=./generated/dog6', '--model_name=stabilityai/stable-diffusion-xl-base-1.0', '--log_dir=./logs/generation_logs']' returned non-zero exit status 1.
