05/17/2024 15:54:03 - INFO - __main__ - Distributed environment: NO
Num processes: 1
Process index: 0
Local process index: 0
Device: cuda

Mixed precision type: no

Couldn't connect to the Hub: 401 Client Error. (Request ID: Root=1-6647617b-7d44b0cc4ee8684c7d79b092;3911f583-af18-4bd1-8f63-a9ab8aa41490)

Repository Not Found for url: https://huggingface.co/api/models/CompVis/stable-diffusion-xl-base.
Please make sure you specified the correct `repo_id` and `repo_type`.
If you are trying to access a private or gated repo, make sure you are authenticated.
Invalid username or password..
Will try to load from local cache.
Traceback (most recent call last):
  File "/net/tscratch/people/plgfilipeckijan/.conda/envs/zzsn_project_env/lib/python3.9/site-packages/huggingface_hub/utils/_errors.py", line 304, in hf_raise_for_status
    response.raise_for_status()
  File "/net/tscratch/people/plgfilipeckijan/.conda/envs/zzsn_project_env/lib/python3.9/site-packages/requests/models.py", line 1021, in raise_for_status
    raise HTTPError(http_error_msg, response=self)
requests.exceptions.HTTPError: 401 Client Error: Unauthorized for url: https://huggingface.co/api/models/CompVis/stable-diffusion-xl-base

The above exception was the direct cause of the following exception:

Traceback (most recent call last):
  File "/net/tscratch/people/plgfilipeckijan/.conda/envs/zzsn_project_env/lib/python3.9/site-packages/diffusers/pipelines/pipeline_utils.py", line 1297, in download
    info = model_info(pretrained_model_name, token=token, revision=revision)
  File "/net/tscratch/people/plgfilipeckijan/.conda/envs/zzsn_project_env/lib/python3.9/site-packages/huggingface_hub/utils/_validators.py", line 119, in _inner_fn
    return fn(*args, **kwargs)
  File "/net/tscratch/people/plgfilipeckijan/.conda/envs/zzsn_project_env/lib/python3.9/site-packages/huggingface_hub/hf_api.py", line 2228, in model_info
    hf_raise_for_status(r)
  File "/net/tscratch/people/plgfilipeckijan/.conda/envs/zzsn_project_env/lib/python3.9/site-packages/huggingface_hub/utils/_errors.py", line 352, in hf_raise_for_status
    raise RepositoryNotFoundError(message, response) from e
huggingface_hub.utils._errors.RepositoryNotFoundError: 401 Client Error. (Request ID: Root=1-6647617b-7d44b0cc4ee8684c7d79b092;3911f583-af18-4bd1-8f63-a9ab8aa41490)

Repository Not Found for url: https://huggingface.co/api/models/CompVis/stable-diffusion-xl-base.
Please make sure you specified the correct `repo_id` and `repo_type`.
If you are trying to access a private or gated repo, make sure you are authenticated.
Invalid username or password.

The above exception was the direct cause of the following exception:

Traceback (most recent call last):
  File "/net/tscratch/people/plgfilipeckijan/zzsn-project/train_dreambooth_sdxl.py", line 1443, in <module>
    main(args)
  File "/net/tscratch/people/plgfilipeckijan/zzsn-project/train_dreambooth_sdxl.py", line 874, in main
    pipeline = DiffusionPipeline.from_pretrained(
  File "/net/tscratch/people/plgfilipeckijan/.conda/envs/zzsn_project_env/lib/python3.9/site-packages/huggingface_hub/utils/_validators.py", line 119, in _inner_fn
    return fn(*args, **kwargs)
  File "/net/tscratch/people/plgfilipeckijan/.conda/envs/zzsn_project_env/lib/python3.9/site-packages/diffusers/pipelines/pipeline_utils.py", line 698, in from_pretrained
    cached_folder = cls.download(
  File "/net/tscratch/people/plgfilipeckijan/.conda/envs/zzsn_project_env/lib/python3.9/site-packages/huggingface_hub/utils/_validators.py", line 119, in _inner_fn
    return fn(*args, **kwargs)
  File "/net/tscratch/people/plgfilipeckijan/.conda/envs/zzsn_project_env/lib/python3.9/site-packages/diffusers/pipelines/pipeline_utils.py", line 1545, in download
    raise EnvironmentError(
OSError: Cannot load model CompVis/stable-diffusion-xl-base: model is not cached locally and an error occurred while trying to fetch metadata from the Hub. Please check out the root cause in the stacktrace above.
Traceback (most recent call last):
  File "/net/tscratch/people/plgfilipeckijan/.conda/envs/zzsn_project_env/bin/accelerate", line 8, in <module>
    sys.exit(main())
  File "/net/tscratch/people/plgfilipeckijan/.conda/envs/zzsn_project_env/lib/python3.9/site-packages/accelerate/commands/accelerate_cli.py", line 46, in main
    args.func(args)
  File "/net/tscratch/people/plgfilipeckijan/.conda/envs/zzsn_project_env/lib/python3.9/site-packages/accelerate/commands/launch.py", line 1075, in launch_command
    simple_launcher(args)
  File "/net/tscratch/people/plgfilipeckijan/.conda/envs/zzsn_project_env/lib/python3.9/site-packages/accelerate/commands/launch.py", line 681, in simple_launcher
    raise subprocess.CalledProcessError(returncode=process.returncode, cmd=cmd)
subprocess.CalledProcessError: Command '['/net/tscratch/people/plgfilipeckijan/.conda/envs/zzsn_project_env/bin/python', 'train_dreambooth_sdxl.py', '--pretrained_model_name_or_path=CompVis/stable-diffusion-xl-base', '--instance_data_dir=./dataset/dreambooth_main/dataset/dog6', '--class_data_dir=./dataset/dreambooth_generated/dog', '--output_dir=./models/dreambooth_sdxl_dog6', '--with_prior_preservation', '--prior_loss_weight=1.0', '--instance_prompt=a sks dog', '--class_prompt=a dog', '--resolution=512', '--train_batch_size=1', '--gradient_accumulation_steps=1', '--learning_rate=5e-6', '--lr_scheduler=constant', '--lr_warmup_steps=0', '--num_class_images=200', '--max_train_steps=800']' returned non-zero exit status 1.
/var/spool/slurmd/job713533/slurm_script: line 40: --logging_dir=./logs/tensorboard_logs: No such file or directory
/var/spool/slurmd/job713533/slurm_script: line 41: --report_to=tensorboard: command not found
