05/20/2024 22:53:28 - INFO - __main__ - Distributed environment: DistributedType.NO
Num processes: 1
Process index: 0
Local process index: 0
Device: cuda

Mixed precision type: no

Traceback (most recent call last):
  File "/net/tscratch/people/plgas2000/.conda/envs/env_zzsn/lib/python3.12/site-packages/huggingface_hub/utils/_errors.py", line 304, in hf_raise_for_status
    response.raise_for_status()
  File "/net/tscratch/people/plgas2000/.conda/envs/env_zzsn/lib/python3.12/site-packages/requests/models.py", line 1024, in raise_for_status
    raise HTTPError(http_error_msg, response=self)
requests.exceptions.HTTPError: 404 Client Error: Not Found for url: https://huggingface.co/stabilityai/sdxl-vae/resolve/main/model_index.json

The above exception was the direct cause of the following exception:

Traceback (most recent call last):
  File "/net/tscratch/people/plgas2000/zzsn-project/train_dreambooth_sdxl.py", line 1443, in <module>
    main(args)
  File "/net/tscratch/people/plgas2000/zzsn-project/train_dreambooth_sdxl.py", line 874, in main
    pipeline = DiffusionPipeline.from_pretrained(
               ^^^^^^^^^^^^^^^^^^^^^^^^^^^^^^^^^^
  File "/net/tscratch/people/plgas2000/.conda/envs/env_zzsn/lib/python3.12/site-packages/huggingface_hub/utils/_validators.py", line 119, in _inner_fn
    return fn(*args, **kwargs)
           ^^^^^^^^^^^^^^^^^^^
  File "/net/tscratch/people/plgas2000/.conda/envs/env_zzsn/lib/python3.12/site-packages/diffusers/pipelines/pipeline_utils.py", line 702, in from_pretrained
    cached_folder = cls.download(
                    ^^^^^^^^^^^^^
  File "/net/tscratch/people/plgas2000/.conda/envs/env_zzsn/lib/python3.12/site-packages/huggingface_hub/utils/_validators.py", line 119, in _inner_fn
    return fn(*args, **kwargs)
           ^^^^^^^^^^^^^^^^^^^
  File "/net/tscratch/people/plgas2000/.conda/envs/env_zzsn/lib/python3.12/site-packages/diffusers/pipelines/pipeline_utils.py", line 1307, in download
    config_file = hf_hub_download(
                  ^^^^^^^^^^^^^^^^
  File "/net/tscratch/people/plgas2000/.conda/envs/env_zzsn/lib/python3.12/site-packages/huggingface_hub/utils/_validators.py", line 119, in _inner_fn
    return fn(*args, **kwargs)
           ^^^^^^^^^^^^^^^^^^^
  File "/net/tscratch/people/plgas2000/.conda/envs/env_zzsn/lib/python3.12/site-packages/huggingface_hub/file_download.py", line 1261, in hf_hub_download
    metadata = get_hf_file_metadata(
               ^^^^^^^^^^^^^^^^^^^^^
  File "/net/tscratch/people/plgas2000/.conda/envs/env_zzsn/lib/python3.12/site-packages/huggingface_hub/utils/_validators.py", line 119, in _inner_fn
    return fn(*args, **kwargs)
           ^^^^^^^^^^^^^^^^^^^
  File "/net/tscratch/people/plgas2000/.conda/envs/env_zzsn/lib/python3.12/site-packages/huggingface_hub/file_download.py", line 1674, in get_hf_file_metadata
    r = _request_wrapper(
        ^^^^^^^^^^^^^^^^^
  File "/net/tscratch/people/plgas2000/.conda/envs/env_zzsn/lib/python3.12/site-packages/huggingface_hub/file_download.py", line 369, in _request_wrapper
    response = _request_wrapper(
               ^^^^^^^^^^^^^^^^^
  File "/net/tscratch/people/plgas2000/.conda/envs/env_zzsn/lib/python3.12/site-packages/huggingface_hub/file_download.py", line 393, in _request_wrapper
    hf_raise_for_status(response)
  File "/net/tscratch/people/plgas2000/.conda/envs/env_zzsn/lib/python3.12/site-packages/huggingface_hub/utils/_errors.py", line 315, in hf_raise_for_status
    raise EntryNotFoundError(message, response) from e
huggingface_hub.utils._errors.EntryNotFoundError: 404 Client Error. (Request ID: Root=1-664bb848-485f4f803867f5516d7b0912;127e39de-65b7-43e8-ad40-e646298d7706)

Entry Not Found for url: https://huggingface.co/stabilityai/sdxl-vae/resolve/main/model_index.json.
Traceback (most recent call last):
  File "/net/tscratch/people/plgas2000/.conda/envs/env_zzsn/bin/accelerate", line 8, in <module>
    sys.exit(main())
             ^^^^^^
  File "/net/tscratch/people/plgas2000/.conda/envs/env_zzsn/lib/python3.12/site-packages/accelerate/commands/accelerate_cli.py", line 46, in main
    args.func(args)
  File "/net/tscratch/people/plgas2000/.conda/envs/env_zzsn/lib/python3.12/site-packages/accelerate/commands/launch.py", line 1075, in launch_command
    simple_launcher(args)
  File "/net/tscratch/people/plgas2000/.conda/envs/env_zzsn/lib/python3.12/site-packages/accelerate/commands/launch.py", line 681, in simple_launcher
    raise subprocess.CalledProcessError(returncode=process.returncode, cmd=cmd)
subprocess.CalledProcessError: Command '['/net/tscratch/people/plgas2000/.conda/envs/env_zzsn/bin/python', 'train_dreambooth_sdxl.py', '--pretrained_model_name_or_path=stabilityai/stable-diffusion-xl-base-1.0', '--instance_data_dir=./dataset/dreambooth-main/dataset/dog6', '--class_data_dir=./dataset/dreambooth_generated/dog', '--output_dir=./models/dreambooth_sdxl_dog6', '--pretrained_model_name_or_path=stabilityai/sdxl-vae', '--with_prior_preservation', '--prior_loss_weight=1.0', '--instance_prompt=a sks dog', '--class_prompt=a dog', '--resolution=512', '--train_batch_size=1', '--gradient_accumulation_steps=1', '--learning_rate=5e-6', '--lr_scheduler=constant', '--lr_warmup_steps=0', '--num_class_images=200', '--max_train_steps=800', '--logging_dir=./logs/tensorboard_logs', '--report_to=tensorboard']' returned non-zero exit status 1.
