The following values were not passed to `accelerate launch` and had defaults used instead:
	`--num_processes` was set to a value of `1`
	`--num_machines` was set to a value of `1`
	`--mixed_precision` was set to a value of `'no'`
	`--dynamo_backend` was set to a value of `'no'`
To avoid this warning pass in values for each of the problematic parameters or run `accelerate config`.
05/27/2024 00:59:31 - INFO - __main__ - Distributed environment: NO
Num processes: 1
Process index: 0
Local process index: 0
Device: cuda

Mixed precision type: fp16

You are using a model of type clip_text_model to instantiate a model of type . This is not supported for all configurations of models and can yield errors.
You are using a model of type clip_text_model to instantiate a model of type . This is not supported for all configurations of models and can yield errors.
{'variance_type', 'thresholding', 'clip_sample_range', 'rescale_betas_zero_snr', 'dynamic_thresholding_ratio'} was not found in config. Values will be initialized to default values.
{'latents_std', 'latents_mean'} was not found in config. Values will be initialized to default values.
Traceback (most recent call last):
  File "/net/people/plgrid/plgas2000/.local/lib/python3.9/site-packages/huggingface_hub/utils/_errors.py", line 304, in hf_raise_for_status
    response.raise_for_status()
  File "/net/tscratch/people/plgas2000/.conda/envs/env_zzsn/lib/python3.9/site-packages/requests/models.py", line 1024, in raise_for_status
    raise HTTPError(http_error_msg, response=self)
requests.exceptions.HTTPError: 404 Client Error: Not Found for url: https://huggingface.co/stabilityai/stable-diffusion-xl-base-1.0/resolve/462165984030d82259a11f4367a4eed129e94a7b/unet/diffusion_pytorch_model.bin

The above exception was the direct cause of the following exception:

Traceback (most recent call last):
  File "/net/people/plgrid/plgas2000/.local/lib/python3.9/site-packages/huggingface_hub/file_download.py", line 1261, in hf_hub_download
    metadata = get_hf_file_metadata(
  File "/net/people/plgrid/plgas2000/.local/lib/python3.9/site-packages/huggingface_hub/utils/_validators.py", line 119, in _inner_fn
    return fn(*args, **kwargs)
  File "/net/people/plgrid/plgas2000/.local/lib/python3.9/site-packages/huggingface_hub/file_download.py", line 1674, in get_hf_file_metadata
    r = _request_wrapper(
  File "/net/people/plgrid/plgas2000/.local/lib/python3.9/site-packages/huggingface_hub/file_download.py", line 369, in _request_wrapper
    response = _request_wrapper(
  File "/net/people/plgrid/plgas2000/.local/lib/python3.9/site-packages/huggingface_hub/file_download.py", line 393, in _request_wrapper
    hf_raise_for_status(response)
  File "/net/people/plgrid/plgas2000/.local/lib/python3.9/site-packages/huggingface_hub/utils/_errors.py", line 315, in hf_raise_for_status
    raise EntryNotFoundError(message, response) from e
huggingface_hub.utils._errors.EntryNotFoundError: 404 Client Error. (Request ID: Root=1-6653bf45-0e34d0705dcea39b1815ddda;2ac85f04-ad61-46ce-96a1-a47ac193bd0b)

Entry Not Found for url: https://huggingface.co/stabilityai/stable-diffusion-xl-base-1.0/resolve/462165984030d82259a11f4367a4eed129e94a7b/unet/diffusion_pytorch_model.bin.

During handling of the above exception, another exception occurred:

Traceback (most recent call last):
  File "/net/tscratch/people/plgas2000/.conda/envs/env_zzsn/lib/python3.9/site-packages/diffusers/utils/hub_utils.py", line 343, in _get_model_file
    model_file = hf_hub_download(
  File "/net/people/plgrid/plgas2000/.local/lib/python3.9/site-packages/huggingface_hub/utils/_validators.py", line 119, in _inner_fn
    return fn(*args, **kwargs)
  File "/net/people/plgrid/plgas2000/.local/lib/python3.9/site-packages/huggingface_hub/file_download.py", line 1275, in hf_hub_download
    no_exist_file_path.parent.mkdir(parents=True, exist_ok=True)
  File "/net/tscratch/people/plgas2000/.conda/envs/env_zzsn/lib/python3.9/pathlib.py", line 1323, in mkdir
    self._accessor.mkdir(self, mode)
OSError: [Errno 122] Disk quota exceeded: '/net/people/plgrid/plgas2000/.cache/huggingface/hub/models--stabilityai--stable-diffusion-xl-base-1.0/.no_exist/462165984030d82259a11f4367a4eed129e94a7b/unet'

During handling of the above exception, another exception occurred:

Traceback (most recent call last):
  File "/net/tscratch/people/plgas2000/zzsn-project/scripts/train/train_dreambooth_ziplora_sdxl.py", line 1817, in <module>
    main(args)
  File "/net/tscratch/people/plgas2000/zzsn-project/scripts/train/train_dreambooth_ziplora_sdxl.py", line 956, in main
    unet = UNet2DConditionModel.from_pretrained(
  File "/net/people/plgrid/plgas2000/.local/lib/python3.9/site-packages/huggingface_hub/utils/_validators.py", line 119, in _inner_fn
    return fn(*args, **kwargs)
  File "/net/tscratch/people/plgas2000/.conda/envs/env_zzsn/lib/python3.9/site-packages/diffusers/models/modeling_utils.py", line 610, in from_pretrained
    model_file = _get_model_file(
  File "/net/people/plgrid/plgas2000/.local/lib/python3.9/site-packages/huggingface_hub/utils/_validators.py", line 119, in _inner_fn
    return fn(*args, **kwargs)
  File "/net/tscratch/people/plgas2000/.conda/envs/env_zzsn/lib/python3.9/site-packages/diffusers/utils/hub_utils.py", line 388, in _get_model_file
    raise EnvironmentError(
OSError: Can't load the model for 'stabilityai/stable-diffusion-xl-base-1.0'. If you were trying to load it from 'https://huggingface.co/models', make sure you don't have a local directory with the same name. Otherwise, make sure 'stabilityai/stable-diffusion-xl-base-1.0' is the correct path to a directory containing a file named diffusion_pytorch_model.bin
Traceback (most recent call last):
  File "/net/tscratch/people/plgas2000/.conda/envs/env_zzsn/bin/accelerate", line 8, in <module>
    sys.exit(main())
  File "/net/people/plgrid/plgas2000/.local/lib/python3.9/site-packages/accelerate/commands/accelerate_cli.py", line 46, in main
    args.func(args)
  File "/net/people/plgrid/plgas2000/.local/lib/python3.9/site-packages/accelerate/commands/launch.py", line 1075, in launch_command
    simple_launcher(args)
  File "/net/people/plgrid/plgas2000/.local/lib/python3.9/site-packages/accelerate/commands/launch.py", line 681, in simple_launcher
    raise subprocess.CalledProcessError(returncode=process.returncode, cmd=cmd)
subprocess.CalledProcessError: Command '['/net/tscratch/people/plgas2000/.conda/envs/env_zzsn/bin/python', 'scripts/train/train_dreambooth_ziplora_sdxl.py', '--pretrained_model_name_or_path=stabilityai/stable-diffusion-xl-base-1.0', '--output_dir=./models/ziplora_dog3_style1_cartoon_2024-05-27_00-59-24', '--lora_name_or_path=./models/dreambooth_lora_sdxl_dog3_2024-05-24_23-43-20', '--instance_prompt=a photo of sks dog', '--instance_data_dir=./dataset/dreambooth-main/dataset/dog3', '--lora_name_or_path_2=./models/dreambooth_lora_sdxl_style1_cartoon_2024-05-26_23-37-49', '--instance_prompt_2=a cat of in crt style', '--instance_data_dir_2=./dataset/styles/style1-cartoon', '--resolution=1024', '--train_batch_size=1', '--learning_rate=5e-5', '--similarity_lambda=0.01', '--lr_scheduler=constant', '--lr_warmup_steps=0', '--max_train_steps=100', '--validation_prompt=a photo of sks dog in crt style', '--validation_epochs=10', '--mixed_precision=fp16', '--report_to=tensorboard', '--enable_xformers_memory_efficient_attention', '--logging_dir=./logs/tensorboard_logs']' returned non-zero exit status 1.
