The following values were not passed to `accelerate launch` and had defaults used instead:
	`--num_processes` was set to a value of `1`
	`--num_machines` was set to a value of `1`
	`--mixed_precision` was set to a value of `'no'`
	`--dynamo_backend` was set to a value of `'no'`
To avoid this warning pass in values for each of the problematic parameters or run `accelerate config`.
/net/tscratch/people/plgas2000/.conda/envs/env_zzsn/lib/python3.9/site-packages/diffusers/utils/outputs.py:63: UserWarning: torch.utils._pytree._register_pytree_node is deprecated. Please use torch.utils._pytree.register_pytree_node instead.
  torch.utils._pytree._register_pytree_node(
05/27/2024 21:18:41 - INFO - __main__ - Distributed environment: NO
Num processes: 1
Process index: 0
Local process index: 0
Device: cuda

Mixed precision type: fp16

Traceback (most recent call last):
  File "/net/people/plgrid/plgas2000/.local/lib/python3.9/site-packages/huggingface_hub/utils/_errors.py", line 304, in hf_raise_for_status
    response.raise_for_status()
  File "/net/tscratch/people/plgas2000/.conda/envs/env_zzsn/lib/python3.9/site-packages/requests/models.py", line 1024, in raise_for_status
    raise HTTPError(http_error_msg, response=self)
requests.exceptions.HTTPError: 401 Client Error: Unauthorized for url: https://huggingface.co/api/repos/create

The above exception was the direct cause of the following exception:

Traceback (most recent call last):
  File "/net/tscratch/people/plgas2000/zzsn-project/scripts/train_ziplora/train_dreambooth_lora_sdxl.py", line 2013, in <module>
    main(args)
  File "/net/tscratch/people/plgas2000/zzsn-project/scripts/train_ziplora/train_dreambooth_lora_sdxl.py", line 1012, in main
    repo_id = create_repo(
  File "/net/people/plgrid/plgas2000/.local/lib/python3.9/site-packages/huggingface_hub/utils/_validators.py", line 119, in _inner_fn
    return fn(*args, **kwargs)
  File "/net/people/plgrid/plgas2000/.local/lib/python3.9/site-packages/huggingface_hub/hf_api.py", line 3360, in create_repo
    hf_raise_for_status(r)
  File "/net/people/plgrid/plgas2000/.local/lib/python3.9/site-packages/huggingface_hub/utils/_errors.py", line 371, in hf_raise_for_status
    raise HfHubHTTPError(str(e), response=response) from e
huggingface_hub.utils._errors.HfHubHTTPError: 401 Client Error: Unauthorized for url: https://huggingface.co/api/repos/create (Request ID: Root=1-6654dc91-4c8c029c558d0e2814e5a081;68163902-23e2-48ea-ba7f-8c8838d33eb6)

Invalid username or password.
Traceback (most recent call last):
  File "/net/tscratch/people/plgas2000/.conda/envs/env_zzsn/bin/accelerate", line 8, in <module>
    sys.exit(main())
  File "/net/tscratch/people/plgas2000/.conda/envs/env_zzsn/lib/python3.9/site-packages/accelerate/commands/accelerate_cli.py", line 46, in main
    args.func(args)
  File "/net/tscratch/people/plgas2000/.conda/envs/env_zzsn/lib/python3.9/site-packages/accelerate/commands/launch.py", line 1075, in launch_command
    simple_launcher(args)
  File "/net/tscratch/people/plgas2000/.conda/envs/env_zzsn/lib/python3.9/site-packages/accelerate/commands/launch.py", line 681, in simple_launcher
    raise subprocess.CalledProcessError(returncode=process.returncode, cmd=cmd)
subprocess.CalledProcessError: Command '['/net/tscratch/people/plgas2000/.conda/envs/env_zzsn/bin/python', 'scripts/train_ziplora/train_dreambooth_lora_sdxl.py', '--pretrained_model_name_or_path=stabilityai/stable-diffusion-xl-base-1.0', '--instance_data_dir=./dataset/styles/style1-cartoon', '--output_dir=./models/dreambooth_lora_sdxl_style1_cartoon_2024-05-27_21-18-28', '--instance_prompt=a cat of in crt style', '--rank=64', '--resolution=1024', '--train_batch_size=1', '--learning_rate=5e-5', '--report_to=wandb', '--lr_scheduler=constant', '--lr_warmup_steps=0', '--max_train_steps=1000', '--validation_prompt=a man in crt style', '--validation_epochs=50', '--seed=0', '--mixed_precision=fp16', '--enable_xformers_memory_efficient_attention', '--gradient_checkpointing', '--use_8bit_adam', '--push_to_hub']' returned non-zero exit status 1.
